Workbook

Sheet Notes
A2: Game Type by team results

Sheet Holidays
A1: holiday_id | B1: Country | C1: Area | D1: team_1 | E1: team_2 | F1: team_1_captain | G1: team_2_captain | H1: long_drive | I1: nearest_pin
A2: 1 | B2: Portugal | C2: Amendoeira | D2: Europe | E2: USA | F2: Watters | G2: J. Witt | H2: O'Rourke | I2: J. Witt
A3: 2 | B3: Spain | C3: Murcia | D3: Europe | E3: USA | F3: D. Witt | G3: McLachlan | H3: O'Rourke | I3: O'Rourke
A4: 3 | B4: Spain | C4: Malaga | D4: Europe | E4: USA | F4: O'Rourke | G4: Lowy | H4: Cranham | I4: Cranham
A5: 4 | B5: Turkey | C5: Belek | D5: Europe | E5: USA | F5: Cranham | G5: James | H5: Condon | I5: James

Sheet Matchdays
A1: event_id | B1: holiday_id | C1: Date | D1: Course | E1: Format | F1: DOTD | G1: Description
A2: 1 | B2: 1 | C2: 44707 | D2: Faldo | E2: Texas Scramble | F2: McLachlan | G2: Copying AJ smashing the ball into a tree and it going backwards
A3: 2 | B3: 1 | C3: 44708 | D3: O'Connor | E3: Fourball | F3: Condon | G3: Driving the ball at the buggie in front
A4: 3 | B4: 1 | C4: 44708 | D4: O'Connor | E4: Singles
A5: 4 | B5: 1 | C5: 44708 | D5: O'Connor | E5: Kingpin
A6: 5 | B6: 1 | C6: 44709 | D6: Faldo | E6: Singles | F6: James | G6: Getting incredibly sunburnt and hiding in the bushes on the 18th
A7: 5 | B7: 1 | C7: 44709 | D7: Faldo | E7: Singles | F7: Rogers | G7: Missing the ball on the first in front of everyone
A8: 6 | B8: 1 | C8: 44710 | D8: O'Connor | E8: Texas Scramble | F8: Condon | G8: Scorecard fuck up
A9: 7 | B9: 2 | C9: 45071 | D9: Hacienda del Almo | E9: 2x2 Scramble | F9: S. Barker | G9: Throwing up off the apartment balconies
A10: 8 | B10: 2 | C10: 45072 | D10: Hacienda del Almo | E10: Fourball | F10: Condon | G10: Pissing on the course
A11: 9 | B11: 2 | C11: 45073 | D11: Saurines | E11: Singles | F11: James | G11: Letting Cal win a hole with an 8
A12: 10 | B12: 2 | C12: 45074 | D12: Saurines | E12: Green Jacket | F12: C. Peters | G12: Running over Cranham in the buggie
A13: 11 | B13: 3 | C13: 45546 | D13: Miguel Angel Jimenez Academy | E13: Green Jacket | F13: S. Barker | G13: Pissing on the course in a well
A14: 12 | B14: 3 | C14: 45547 | D14: Calanova | E14: 2x2 Scramble | F14: D. Witt | G14: Being sick on the course
A15: 13 | B15: 3 | C15: 45548 | D15: El Chaparral | E15: Fourball | F15: James | G15: Missing tee shot again
A16: 13.5 | B16: 3 | C16: 45549 | D16: Marbella | F16: Brown | G16: Shaking the tree
A17: 14 | B17: 3 | C17: 45550 | D17: La Cala (Asia) | E17: Singles | F17: Watters | G17: Chair in sea, hit house
A18: 15 | B18: 4 | C18: 45791 | D18: Kaya Belek | E18: 2x2 Scramble | F18: James | G18: Smashing everything on the table
A19: 16 | B19: 4 | C19: 45792 | D19: Carya | E19: Fourball | F19: Condon | G19: Pissing on the course
A20: 17 | B20: 4 | C20: 45793 | D20: Kaya Belek | E20: Singles | F20: Mulligan | G20: Javelining club down the fairway and forgetting about it with it stuck in the ground
A21: 18 | B21: 4 | C21: 45794 | D21: Montgomerie | E21: Green Jacket | F21: Condon | G21: Disobeying cabbie

Sheet Matches
A1: Date | B1: event_id | C1: holiday_id | D1: Country | E1: Area | F1: Course | G1: Format | H1: match_id | I1: player_a | J1: player_b | K1: player_c | L1: player_d | M1: team_a | N1: team_b | O1: team_c | P1: team_d | Q1: Result | R1: Score | S1: captain_europe | T1: captain_usa | U1: points_a | V1: points_b | W1: points_c | X1: points_d | Y1: chip_in_a | Z1: chip_in_b | AA1: chip_in_c | AB1: chip_in_d | AC1: birdie_a | AD1: birdie_b | AE1: birdie_c | AF1: birdie_d
A2: =vlookup($B2,Matchdays!$A$2:$E$20,3) -> 44707 | B2: 1 | C2: =vlookup($B2,Matchdays!$A$2:$E$20,2) -> 1 | D2: =vlookup($C2,Holidays!$A:$G,2) -> Portugal | E2: =vlookup($C2,Holidays!$A:$G,3) -> Amendoeira | F2: =vlookup($B2,Matchdays!$A$2:$E$20,4) -> Faldo | G2: =vlookup($B2,Matchdays!$A$2:$E$20,5) -> Texas Scramble | H2: 1 | I2: James | J2: McLachlan | K2: Condon | M2: USA | N2: USA | O2: USA | Q2: 1 | R2: =4 -> 4 | S2: =vlookup($C2,Holidays!$A:$G,6) -> Watters | T2: =vlookup($C2,Holidays!$A:$G,7) -> J. Witt | U2: =2.5/3 -> 0.83333333 | V2: =2.5/3 -> 0.83333333 | W2: =2.5/3 -> 0.83333333 | X2: =if(P2=$Q$2,1,0) -> 0
A3: =vlookup($B3,Matchdays!$A$2:$E$20,3) -> 44707 | B3: 1 | C3: =vlookup($B3,Matchdays!$A$2:$E$20,2) -> 1 | D3: =vlookup($C3,Holidays!$A:$G,2) -> Portugal | E3: =vlookup($C3,Holidays!$A:$G,3) -> Amendoeira | F3: =vlookup($B3,Matchdays!$A$2:$E$20,4) -> Faldo | G3: =vlookup($B3,Matchdays!$A$2:$E$20,5) -> Texas Scramble | H3: 1 | I3: O'Rourke | J3: D. Witt | K3: Mulligan | M3: Europe | N3: Europe | O3: Europe | Q3: 1 | R3: =4 -> 4 | S3: =vlookup($C3,Holidays!$A:$G,6) -> Watters | T3: =vlookup($C3,Holidays!$A:$G,7) -> J. Witt | U3: =2.5/3 -> 0.83333333 | V3: =2.5/3 -> 0.83333333 | W3: =2.5/3 -> 0.83333333 | X3: =if(P3=$Q$2,1,0) -> 0
A4: =vlookup($B4,Matchdays!$A$2:$E$20,3) -> 44707 | B4: 1 | C4: =vlookup($B4,Matchdays!$A$2:$E$20,2) -> 1 | D4: =vlookup($C4,Holidays!$A:$G,2) -> Portugal | E4: =vlookup($C4,Holidays!$A:$G,3) -> Amendoeira | F4: =vlookup($B4,Matchdays!$A$2:$E$20,4) -> Faldo | G4: =vlookup($B4,Matchdays!$A$2:$E$20,5) -> Texas Scramble | H4: 1 | I4: Watters | J4: C. Peters | K4: Rogers | L4: Cranham | M4: Europe | N4: Europe | O4: Europe | P4: Europe | Q4: 3 | R4: 6 | S4: =vlookup($C4,Holidays!$A:$G,6) -> Watters | T4: =vlookup($C4,Holidays!$A:$G,7) -> J. Witt | U4: 0.25 | V4: 0.25 | W4: 0.25 | X4: 0.25
A5: =vlookup($B5,Matchdays!$A$2:$E$20,3) -> 44707 | B5: 1 | C5: =vlookup($B5,Matchdays!$A$2:$E$20,2) -> 1 | D5: =vlookup($C5,Holidays!$A:$G,2) -> Portugal | E5: =vlookup($C5,Holidays!$A:$G,3) -> Amendoeira | F5: =vlookup($B5,Matchdays!$A$2:$E$20,4) -> Faldo | G5: =vlookup($B5,Matchdays!$A$2:$E$20,5) -> Texas Scramble | H5: 1 | I5: Lowy | J5: J. Witt | K5: S. Barker | M5: USA | N5: USA | O5: USA | Q5: 4 | R5: 9 | S5: =vlookup($C5,Holidays!$A:$G,6) -> Watters | T5: =vlookup($C5,Holidays!$A:$G,7) -> J. Witt | U5: =if(M5=$Q$2,1,0) -> 0 | V5: =if(N5=$Q$2,1,0) -> 0 | W5: =if(O5=$Q$2,1,0) -> 0 | X5: =if(P5=$Q$2,1,0) -> 0
A6: =vlookup($B6,Matchdays!$A$2:$E$20,3) -> 44708 | B6: 2 | C6: =vlookup($B6,Matchdays!$A$2:$E$20,2) -> 1 | D6: =vlookup($C6,Holidays!$A:$G,2) -> Portugal | E6: =vlookup($C6,Holidays!$A:$G,3) -> Amendoeira | F6: =vlookup($B6,Matchdays!$A$2:$E$20,4) -> O'Connor | G6: =vlookup($B6,Matchdays!$A$2:$E$20,5) -> Fourball | H6: 2 | I6: Watters | J6: Mulligan | K6: S. Barker | L6: Condon | M6: Europe | N6: Europe | O6: USA | P6: USA | Q6: Europe | R6: 4&3 | S6: =vlookup($C6,Holidays!$A:$G,6) -> Watters | T6: =vlookup($C6,Holidays!$A:$G,7) -> J. Witt | U6: =if(M6=$Q6,1,if($Q6 = "Tie",0.5,0)) -> 1 | V6: =if(N6=$Q6,1,if($Q6 = "Tie",0.5,0)) -> 1 | W6: =if(O6=$Q6,1,if($Q6 = "Tie",0.5,0)) -> 0 | X6: =if(P6=$Q6,1,if($Q6 = "Tie",0.5,0)) -> 0
A7: =vlookup($B7,Matchdays!$A$2:$E$20,3) -> 44708 | B7: 2 | C7: =vlookup($B7,Matchdays!$A$2:$E$20,2) -> 1 | D7: =vlookup($C7,Holidays!$A:$G,2) -> Portugal | E7: =vlookup($C7,Holidays!$A:$G,3) -> Amendoeira | F7: =vlookup($B7,Matchdays!$A$2:$E$20,4) -> O'Connor | G7: =vlookup($B7,Matchdays!$A$2:$E$20,5) -> Fourball | H7: 3 | I7: D. Witt | J7: Cranham | K7: McLachlan | L7: James | M7: Europe | N7: Europe | O7: USA | P7: USA | Q7: USA | R7: 3&2 | S7: =vlookup($C7,Holidays!$A:$G,6) -> Watters | T7: =vlookup($C7,Holidays!$A:$G,7) -> J. Witt | U7: =if(M7=$Q7,1,if($Q7 = "Tie",0.5,0)) -> 0 | V7: =if(N7=$Q7,1,if($Q7 = "Tie",0.5,0)) -> 0 | W7: =if(O7=$Q7,1,if($Q7 = "Tie",0.5,0)) -> 1 | X7: =if(P7=$Q7,1,if($Q7 = "Tie",0.5,0)) -> 1 | AD7: 1
A8: =vlookup($B8,Matchdays!$A$2:$E$20,3) -> 44708 | B8: 3 | C8: =vlookup($B8,Matchdays!$A$2:$E$20,2) -> 1 | D8: =vlookup($C8,Holidays!$A:$G,2) -> Portugal | E8: =vlookup($C8,Holidays!$A:$G,3) -> Amendoeira | F8: =vlookup($B8,Matchdays!$A$2:$E$20,4) -> O'Connor | G8: =vlookup($B8,Matchdays!$A$2:$E$20,5) -> Singles | H8: 4 | I8: O'Rourke | K8: Lowy | M8: Europe | O8: USA | Q8: Europe | R8: 5&3 | S8: =vlookup($C8,Holidays!$A:$G,6) -> Watters | T8: =vlookup($C8,Holidays!$A:$G,7) -> J. Witt | U8: =if(M8=$Q8,1,if($Q8 = "Tie",0.5,0)) -> 1 | V8: =if(N8=$Q8,1,if($Q8 = "Tie",0.5,0)) -> 0 | W8: =if(O8=$Q8,1,if($Q8 = "Tie",0.5,0)) -> 0 | X8: =if(P8=$Q8,1,if($Q8 = "Tie",0.5,0)) -> 0
A9: =vlookup($B9,Matchdays!$A$2:$E$20,3) -> 44708 | B9: 4 | C9: =vlookup($B9,Matchdays!$A$2:$E$20,2) -> 1 | D9: =vlookup($C9,Holidays!$A:$G,2) -> Portugal | E9: =vlookup($C9,Holidays!$A:$G,3) -> Amendoeira | F9: =vlookup($B9,Matchdays!$A$2:$E$20,4) -> O'Connor | G9: =vlookup($B9,Matchdays!$A$2:$E$20,5) -> Kingpin | H9: 5 | I9: C. Peters | J9: Rogers | K9: J. Witt | M9: Europe | N9: Europe | O9: USA | Q9: USA | R9: 5.5-7 | S9: =vlookup($C9,Holidays!$A:$G,6) -> Watters | T9: =vlookup($C9,Holidays!$A:$G,7) -> J. Witt | U9: =if(M9=$Q9,1,if($Q9 = "Tie",0.5,0)) -> 0 | V9: =if(N9=$Q9,1,if($Q9 = "Tie",0.5,0)) -> 0 | W9: =if(O9=$Q9,1,if($Q9 = "Tie",0.5,0)) -> 1 | X9: =if(P9=$Q9,1,if($Q9 = "Tie",0.5,0)) -> 0
A10: =vlookup($B10,Matchdays!$A$2:$E$20,3) -> 44709 | B10: 5 | C10: =vlookup($B10,Matchdays!$A$2:$E$20,2) -> 1 | D10: =vlookup($C10,Holidays!$A:$G,2) -> Portugal | E10: =vlookup($C10,Holidays!$A:$G,3) -> Amendoeira | F10: =vlookup($B10,Matchdays!$A$2:$E$20,4) -> Faldo | G10: =vlookup($B10,Matchdays!$A$2:$E$20,5) -> Singles | H10: 6 | I10: Watters | K10: J. Witt | M10: Europe | O10: USA | Q10: Europe | R10: 7&5 | S10: =vlookup($C10,Holidays!$A:$G,6) -> Watters | T10: =vlookup($C10,Holidays!$A:$G,7) -> J. Witt | U10: =if(M10=$Q10,1,if($Q10 = "Tie",0.5,0)) -> 1 | V10: =if(N10=$Q10,1,if($Q10 = "Tie",0.5,0)) -> 0 | W10: =if(O10=$Q10,1,if($Q10 = "Tie",0.5,0)) -> 0 | X10: =if(P10=$Q10,1,if($Q10 = "Tie",0.5,0)) -> 0
A11: =vlookup($B11,Matchdays!$A$2:$E$20,3) -> 44709 | B11: 5 | C11: =vlookup($B11,Matchdays!$A$2:$E$20,2) -> 1 | D11: =vlookup($C11,Holidays!$A:$G,2) -> Portugal | E11: =vlookup($C11,Holidays!$A:$G,3) -> Amendoeira | F11: =vlookup($B11,Matchdays!$A$2:$E$20,4) -> Faldo | G11: =vlookup($B11,Matchdays!$A$2:$E$20,5) -> Singles | H11: 7 | I11: C. Peters | K11: McLachlan | M11: Europe | O11: USA | Q11: USA | R11: 2&1 | S11: =vlookup($C11,Holidays!$A:$G,6) -> Watters | T11: =vlookup($C11,Holidays!$A:$G,7) -> J. Witt | U11: =if(M11=$Q11,1,if($Q11 = "Tie",0.5,0)) -> 0 | V11: =if(N11=$Q11,1,if($Q11 = "Tie",0.5,0)) -> 0 | W11: =if(O11=$Q11,1,if($Q11 = "Tie",0.5,0)) -> 1 | X11: =if(P11=$Q11,1,if($Q11 = "Tie",0.5,0)) -> 0
A12: =vlookup($B12,Matchdays!$A$2:$E$20,3) -> 44709 | B12: 5 | C12: =vlookup($B12,Matchdays!$A$2:$E$20,2) -> 1 | D12: =vlookup($C12,Holidays!$A:$G,2) -> Portugal | E12: =vlookup($C12,Holidays!$A:$G,3) -> Amendoeira | F12: =vlookup($B12,Matchdays!$A$2:$E$20,4) -> Faldo | G12: =vlookup($B12,Matchdays!$A$2:$E$20,5) -> Singles | H12: 8 | I12: D. Witt | K12: McLachlan | M12: Europe | O12: USA | Q12: Europe | R12: 2UP | S12: =vlookup($C12,Holidays!$A:$G,6) -> Watters | T12: =vlookup($C12,Holidays!$A:$G,7) -> J. Witt | U12: =if(M12=$Q12,1,if($Q12 = "Tie",0.5,0)) -> 1 | V12: =if(N12=$Q12,1,if($Q12 = "Tie",0.5,0)) -> 0 | W12: =if(O12=$Q12,1,if($Q12 = "Tie",0.5,0)) -> 0 | X12: =if(P12=$Q12,1,if($Q12 = "Tie",0.5,0)) -> 0
A13: =vlookup($B13,Matchdays!$A$2:$E$20,3) -> 44709 | B13: 5 | C13: =vlookup($B13,Matchdays!$A$2:$E$20,2) -> 1 | D13: =vlookup($C13,Holidays!$A:$G,2) -> Portugal | E13: =vlookup($C13,Holidays!$A:$G,3) -> Amendoeira | F13: =vlookup($B13,Matchdays!$A$2:$E$20,4) -> Faldo | G13: =vlookup($B13,Matchdays!$A$2:$E$20,5) -> Singles | H13: 9 | I13: Mulligan | K13: S. Barker | M13: Europe | O13: USA | Q13: USA | R13: 4&3 | S13: =vlookup($C13,Holidays!$A:$G,6) -> Watters | T13: =vlookup($C13,Holidays!$A:$G,7) -> J. Witt | U13: =if(M13=$Q13,1,if($Q13 = "Tie",0.5,0)) -> 0 | V13: =if(N13=$Q13,1,if($Q13 = "Tie",0.5,0)) -> 0 | W13: =if(O13=$Q13,1,if($Q13 = "Tie",0.5,0)) -> 1 | X13: =if(P13=$Q13,1,if($Q13 = "Tie",0.5,0)) -> 0
A14: =vlookup($B14,Matchdays!$A$2:$E$20,3) -> 44709 | B14: 5 | C14: =vlookup($B14,Matchdays!$A$2:$E$20,2) -> 1 | D14: =vlookup($C14,Holidays!$A:$G,2) -> Portugal | E14: =vlookup($C14,Holidays!$A:$G,3) -> Amendoeira | F14: =vlookup($B14,Matchdays!$A$2:$E$20,4) -> Faldo | G14: =vlookup($B14,Matchdays!$A$2:$E$20,5) -> Singles | H14: 10 | I14: Cranham | K14: James | M14: Europe | O14: USA | Q14: Europe | R14: 2&1 | S14: =vlookup($C14,Holidays!$A:$G,6) -> Watters | T14: =vlookup($C14,Holidays!$A:$G,7) -> J. Witt | U14: =if(M14=$Q14,1,if($Q14 = "Tie",0.5,0)) -> 1 | V14: =if(N14=$Q14,1,if($Q14 = "Tie",0.5,0)) -> 0 | W14: =if(O14=$Q14,1,if($Q14 = "Tie",0.5,0)) -> 0 | X14: =if(P14=$Q14,1,if($Q14 = "Tie",0.5,0)) -> 0 | AC14: 1
A15: =vlookup($B15,Matchdays!$A$2:$E$20,3) -> 44709 | B15: 5 | C15: =vlookup($B15,Matchdays!$A$2:$E$20,2) -> 1 | D15: =vlookup($C15,Holidays!$A:$G,2) -> Portugal | E15: =vlookup($C15,Holidays!$A:$G,3) -> Amendoeira | F15: =vlookup($B15,Matchdays!$A$2:$E$20,4) -> Faldo | G15: =vlookup($B15,Matchdays!$A$2:$E$20,5) -> Singles | H15: 11 | I15: Rogers | K15: Lowy | M15: Europe | O15: USA | Q15: USA | R15: 4&3 | S15: =vlookup($C15,Holidays!$A:$G,6) -> Watters | T15: =vlookup($C15,Holidays!$A:$G,7) -> J. Witt | U15: =if(M15=$Q15,1,if($Q15 = "Tie",0.5,0)) -> 0 | V15: =if(N15=$Q15,1,if($Q15 = "Tie",0.5,0)) -> 0 | W15: =if(O15=$Q15,1,if($Q15 = "Tie",0.5,0)) -> 1 | X15: =if(P15=$Q15,1,if($Q15 = "Tie",0.5,0)) -> 0
A16: =vlookup($B16,Matchdays!$A$2:$E$20,3) -> 44709 | B16: 5 | C16: =vlookup($B16,Matchdays!$A$2:$E$20,2) -> 1 | D16: =vlookup($C16,Holidays!$A:$G,2) -> Portugal | E16: =vlookup($C16,Holidays!$A:$G,3) -> Amendoeira | F16: =vlookup($B16,Matchdays!$A$2:$E$20,4) -> Faldo | G16: =vlookup($B16,Matchdays!$A$2:$E$20,5) -> Singles | H16: 12 | I16: O'Rourke | K16: Condon | M16: Europe | O16: USA | Q16: Tie | R16: A/S | S16: =vlookup($C16,Holidays!$A:$G,6) -> Watters | T16: =vlookup($C16,Holidays!$A:$G,7) -> J. Witt | U16: =if(M16=$Q16,1,if($Q16 = "Tie",0.5,0)) -> 0.5 | V16: =if(N16=$Q16,1,if($Q16 = "Tie",0.5,0)) -> 0.5 | W16: =if(O16=$Q16,1,if($Q16 = "Tie",0.5,0)) -> 0.5 | X16: =if(P16=$Q16,1,if($Q16 = "Tie",0.5,0)) -> 0.5 | AE16: 1
A17: =vlookup($B17,Matchdays!$A$2:$E$20,3) -> 44710 | B17: 6 | C17: =vlookup($B17,Matchdays!$A$2:$E$20,2) -> 1 | D17: =vlookup($C17,Holidays!$A:$G,2) -> Portugal | E17: =vlookup($C17,Holidays!$A:$G,3) -> Amendoeira | F17: =vlookup($B17,Matchdays!$A$2:$E$20,4) -> O'Connor | G17: =vlookup($B17,Matchdays!$A$2:$E$20,5) -> Texas Scramble | H17: 13 | I17: McLachlan | J17: J. Witt | K17: Condon | M17: USA | N17: USA | O17: USA | Q17: 1 | R17: -2 | S17: =vlookup($C17,Holidays!$A:$G,6) -> Watters | T17: =vlookup($C17,Holidays!$A:$G,7) -> J. Witt | U17: 1 | V17: 1 | W17: 1 | X17: =if(P17=$Q$2,1,0) -> 0
A18: =vlookup($B18,Matchdays!$A$2:$E$20,3) -> 44710 | B18: 6 | C18: =vlookup($B18,Matchdays!$A$2:$E$20,2) -> 1 | D18: =vlookup($C18,Holidays!$A:$G,2) -> Portugal | E18: =vlookup($C18,Holidays!$A:$G,3) -> Amendoeira | F18: =vlookup($B18,Matchdays!$A$2:$E$20,4) -> O'Connor | G18: =vlookup($B18,Matchdays!$A$2:$E$20,5) -> Texas Scramble | H18: 13 | I18: O'Rourke | J18: D. Witt | K18: Mulligan | M18: Europe | N18: Europe | O18: Europe | Q18: 2 | R18: 0 | S18: =vlookup($C18,Holidays!$A:$G,6) -> Watters | T18: =vlookup($C18,Holidays!$A:$G,7) -> J. Witt | U18: 0.5 | V18: 0.5 | W18: 0.5 | X18: =if(P18=$Q$2,1,0) -> 0
A19: =vlookup($B19,Matchdays!$A$2:$E$20,3) -> 44710 | B19: 6 | C19: =vlookup($B19,Matchdays!$A$2:$E$20,2) -> 1 | D19: =vlookup($C19,Holidays!$A:$G,2) -> Portugal | E19: =vlookup($C19,Holidays!$A:$G,3) -> Amendoeira | F19: =vlookup($B19,Matchdays!$A$2:$E$20,4) -> O'Connor | G19: =vlookup($B19,Matchdays!$A$2:$E$20,5) -> Texas Scramble | H19: 13 | I19: Watters | J19: C. Peters | K19: Rogers | L19: Cranham | M19: Europe | N19: Europe | O19: Europe | P19: Europe | Q19: 2 | R19: 0 | S19: =vlookup($C19,Holidays!$A:$G,6) -> Watters | T19: =vlookup($C19,Holidays!$A:$G,7) -> J. Witt | U19: 0.375 | V19: 0.375 | W19: 0.375 | X19: 0.375
A20: =vlookup($B20,Matchdays!$A$2:$E$20,3) -> 44710 | B20: 6 | C20: =vlookup($B20,Matchdays!$A$2:$E$20,2) -> 1 | D20: =vlookup($C20,Holidays!$A:$G,2) -> Portugal | E20: =vlookup($C20,Holidays!$A:$G,3) -> Amendoeira | F20: =vlookup($B20,Matchdays!$A$2:$E$20,4) -> O'Connor | G20: =vlookup($B20,Matchdays!$A$2:$E$20,5) -> Texas Scramble | H20: 13 | I20: Lowy | J20: S. Barker | K20: James | M20: USA | N20: USA | O20: USA | Q20: 4 | R20: =4 -> 4 | S20: =vlookup($C20,Holidays!$A:$G,6) -> Watters | T20: =vlookup($C20,Holidays!$A:$G,7) -> J. Witt | U20: =if(M20=$Q$2,1,0) -> 0 | V20: =if(N20=$Q$2,1,0) -> 0 | W20: =if(O20=$Q$2,1,0) -> 0 | X20: =if(P20=$Q$2,1,0) -> 0
A21: =vlookup($B21,Matchdays!$A$2:$E$20,3) -> 45071 | B21: 7 | C21: =vlookup($B21,Matchdays!$A$2:$E$20,2) -> 2 | D21: =vlookup($C21,Holidays!$A:$G,2) -> Spain | E21: =vlookup($C21,Holidays!$A:$G,3) -> Murcia | F21: =vlookup($B21,Matchdays!$A$2:$E$20,4) -> Hacienda del Almo | G21: =vlookup($B21,Matchdays!$A$2:$E$20,5) -> 2x2 Scramble | H21: 14 | I21: C. Peters | J21: Cranham | K21: James | L21: S. Barker | M21: Europe | N21: Europe | O21: USA | P21: USA | Q21: Europe | R21: 6&4 | S21: =vlookup($C21,Holidays!$A:$G,6) -> D. Witt | T21: =vlookup($C21,Holidays!$A:$G,7) -> McLachlan | U21: =if(M21=$Q21,1,if($Q21 = "Tie",0.5,0)) -> 1 | V21: =if(N21=$Q21,1,if($Q21 = "Tie",0.5,0)) -> 1 | W21: =if(O21=$Q21,1,if($Q21 = "Tie",0.5,0)) -> 0 | X21: =if(P21=$Q21,1,if($Q21 = "Tie",0.5,0)) -> 0
A22: =vlookup($B22,Matchdays!$A$2:$E$20,3) -> 45071 | B22: 7 | C22: =vlookup($B22,Matchdays!$A$2:$E$20,2) -> 2 | D22: =vlookup($C22,Holidays!$A:$G,2) -> Spain | E22: =vlookup($C22,Holidays!$A:$G,3) -> Murcia | F22: =vlookup($B22,Matchdays!$A$2:$E$20,4) -> Hacienda del Almo | G22: =vlookup($B22,Matchdays!$A$2:$E$20,5) -> 2x2 Scramble | H22: 15 | I22: O'Rourke | J22: Rogers | K22: McLachlan | L22: Condon | M22: Europe | N22: Europe | O22: USA | P22: USA | Q22: Europe | R22: 3&2 | S22: =vlookup($C22,Holidays!$A:$G,6) -> D. Witt | T22: =vlookup($C22,Holidays!$A:$G,7) -> McLachlan | U22: =if(M22=$Q22,1,if($Q22 = "Tie",0.5,0)) -> 1 | V22: =if(N22=$Q22,1,if($Q22 = "Tie",0.5,0)) -> 1 | W22: =if(O22=$Q22,1,if($Q22 = "Tie",0.5,0)) -> 0 | X22: =if(P22=$Q22,1,if($Q22 = "Tie",0.5,0)) -> 0
A23: =vlookup($B23,Matchdays!$A$2:$E$20,3) -> 45071 | B23: 7 | C23: =vlookup($B23,Matchdays!$A$2:$E$20,2) -> 2 | D23: =vlookup($C23,Holidays!$A:$G,2) -> Spain | E23: =vlookup($C23,Holidays!$A:$G,3) -> Murcia | F23: =vlookup($B23,Matchdays!$A$2:$E$20,4) -> Hacienda del Almo | G23: =vlookup($B23,Matchdays!$A$2:$E$20,5) -> 2x2 Scramble | H23: 16 | I23: D. Witt | J23: Watters | K23: J. Witt | L23: Lowy | M23: Europe | N23: Europe | O23: USA | P23: USA | Q23: USA | R23: 1UP | S23: =vlookup($C23,Holidays!$A:$G,6) -> D. Witt | T23: =vlookup($C23,Holidays!$A:$G,7) -> McLachlan | U23: =if(M23=$Q23,1,if($Q23 = "Tie",0.5,0)) -> 0 | V23: =if(N23=$Q23,1,if($Q23 = "Tie",0.5,0)) -> 0 | W23: =if(O23=$Q23,1,if($Q23 = "Tie",0.5,0)) -> 1 | X23: =if(P23=$Q23,1,if($Q23 = "Tie",0.5,0)) -> 1 | Y23: 1
A24: =vlookup($B24,Matchdays!$A$2:$E$20,3) -> 45072 | B24: 8 | C24: =vlookup($B24,Matchdays!$A$2:$E$20,2) -> 2 | D24: =vlookup($C24,Holidays!$A:$G,2) -> Spain | E24: =vlookup($C24,Holidays!$A:$G,3) -> Murcia | F24: =vlookup($B24,Matchdays!$A$2:$E$20,4) -> Hacienda del Almo | G24: =vlookup($B24,Matchdays!$A$2:$E$20,5) -> Fourball | H24: 17 | I24: O'Rourke | J24: Watters | K24: J. Witt | L24: McLachlan | M24: Europe | N24: Europe | O24: USA | P24: USA | Q24: Tie | R24: A/S | S24: =vlookup($C24,Holidays!$A:$G,6) -> D. Witt | T24: =vlookup($C24,Holidays!$A:$G,7) -> McLachlan | U24: =if(M24=$Q24,1,if($Q24 = "Tie",0.5,0)) -> 0.5 | V24: =if(N24=$Q24,1,if($Q24 = "Tie",0.5,0)) -> 0.5 | W24: =if(O24=$Q24,1,if($Q24 = "Tie",0.5,0)) -> 0.5 | X24: =if(P24=$Q24,1,if($Q24 = "Tie",0.5,0)) -> 0.5 | AC24: 1 | AE24: 1
A25: =vlookup($B25,Matchdays!$A$2:$E$20,3) -> 45072 | B25: 8 | C25: =vlookup($B25,Matchdays!$A$2:$E$20,2) -> 2 | D25: =vlookup($C25,Holidays!$A:$G,2) -> Spain | E25: =vlookup($C25,Holidays!$A:$G,3) -> Murcia | F25: =vlookup($B25,Matchdays!$A$2:$E$20,4) -> Hacienda del Almo | G25: =vlookup($B25,Matchdays!$A$2:$E$20,5) -> Fourball | H25: 18 | I25: C. Peters | J25: Cranham | K25: S. Barker | L25: Lowy | M25: Europe | N25: Europe | O25: USA | P25: USA | Q25: Europe | R25: 5&4 | S25: =vlookup($C25,Holidays!$A:$G,6) -> D. Witt | T25: =vlookup($C25,Holidays!$A:$G,7) -> McLachlan | U25: =if(M25=$Q25,1,if($Q25 = "Tie",0.5,0)) -> 1 | V25: =if(N25=$Q25,1,if($Q25 = "Tie",0.5,0)) -> 1 | W25: =if(O25=$Q25,1,if($Q25 = "Tie",0.5,0)) -> 0 | X25: =if(P25=$Q25,1,if($Q25 = "Tie",0.5,0)) -> 0
A26: =vlookup($B26,Matchdays!$A$2:$E$20,3) -> 45072 | B26: 8 | C26: =vlookup($B26,Matchdays!$A$2:$E$20,2) -> 2 | D26: =vlookup($C26,Holidays!$A:$G,2) -> Spain | E26: =vlookup($C26,Holidays!$A:$G,3) -> Murcia | F26: =vlookup($B26,Matchdays!$A$2:$E$20,4) -> Hacienda del Almo | G26: =vlookup($B26,Matchdays!$A$2:$E$20,5) -> Fourball | H26: 19 | I26: D. Witt | J26: Rogers | K26: James | L26: Condon | M26: Europe | N26: Europe | O26: USA | P26: USA | Q26: USA | R26: 1UP | S26: =vlookup($C26,Holidays!$A:$G,6) -> D. Witt | T26: =vlookup($C26,Holidays!$A:$G,7) -> McLachlan | U26: =if(M26=$Q26,1,if($Q26 = "Tie",0.5,0)) -> 0 | V26: =if(N26=$Q26,1,if($Q26 = "Tie",0.5,0)) -> 0 | W26: =if(O26=$Q26,1,if($Q26 = "Tie",0.5,0)) -> 1 | X26: =if(P26=$Q26,1,if($Q26 = "Tie",0.5,0)) -> 1
A27: =vlookup($B27,Matchdays!$A$2:$E$20,3) -> 45073 | B27: 9 | C27: =vlookup($B27,Matchdays!$A$2:$E$20,2) -> 2 | D27: =vlookup($C27,Holidays!$A:$G,2) -> Spain | E27: =vlookup($C27,Holidays!$A:$G,3) -> Murcia | F27: =vlookup($B27,Matchdays!$A$2:$E$20,4) -> Saurines | G27: =vlookup($B27,Matchdays!$A$2:$E$20,5) -> Singles | H27: 20 | I27: D. Witt | K27: McLachlan | M27: Europe | O27: USA | Q27: USA | R27: 3&2 | S27: =vlookup($C27,Holidays!$A:$G,6) -> D. Witt | T27: =vlookup($C27,Holidays!$A:$G,7) -> McLachlan | U27: =if(M27=$Q27,1,if($Q27 = "Tie",0.5,0)) -> 0 | V27: =if(N27=$Q27,1,if($Q27 = "Tie",0.5,0)) -> 0 | W27: =if(O27=$Q27,1,if($Q27 = "Tie",0.5,0)) -> 1 | X27: =if(P27=$Q27,1,if($Q27 = "Tie",0.5,0)) -> 0 | AE27: 1
A28: =vlookup($B28,Matchdays!$A$2:$E$20,3) -> 45073 | B28: 9 | C28: =vlookup($B28,Matchdays!$A$2:$E$20,2) -> 2 | D28: =vlookup($C28,Holidays!$A:$G,2) -> Spain | E28: =vlookup($C28,Holidays!$A:$G,3) -> Murcia | F28: =vlookup($B28,Matchdays!$A$2:$E$20,4) -> Saurines | G28: =vlookup($B28,Matchdays!$A$2:$E$20,5) -> Singles | H28: 21 | I28: C. Peters | K28: James | M28: Europe | O28: USA | Q28: USA | R28: 4&3 | S28: =vlookup($C28,Holidays!$A:$G,6) -> D. Witt | T28: =vlookup($C28,Holidays!$A:$G,7) -> McLachlan | U28: =if(M28=$Q28,1,if($Q28 = "Tie",0.5,0)) -> 0 | V28: =if(N28=$Q28,1,if($Q28 = "Tie",0.5,0)) -> 0 | W28: =if(O28=$Q28,1,if($Q28 = "Tie",0.5,0)) -> 1 | X28: =if(P28=$Q28,1,if($Q28 = "Tie",0.5,0)) -> 0
A29: =vlookup($B29,Matchdays!$A$2:$E$20,3) -> 45073 | B29: 9 | C29: =vlookup($B29,Matchdays!$A$2:$E$20,2) -> 2 | D29: =vlookup($C29,Holidays!$A:$G,2) -> Spain | E29: =vlookup($C29,Holidays!$A:$G,3) -> Murcia | F29: =vlookup($B29,Matchdays!$A$2:$E$20,4) -> Saurines | G29: =vlookup($B29,Matchdays!$A$2:$E$20,5) -> Singles | H29: 22 | I29: O'Rourke | K29: S. Barker | M29: Europe | O29: USA | Q29: Europe | R29: 4&2 | S29: =vlookup($C29,Holidays!$A:$G,6) -> D. Witt | T29: =vlookup($C29,Holidays!$A:$G,7) -> McLachlan | U29: =if(M29=$Q29,1,if($Q29 = "Tie",0.5,0)) -> 1 | V29: =if(N29=$Q29,1,if($Q29 = "Tie",0.5,0)) -> 0 | W29: =if(O29=$Q29,1,if($Q29 = "Tie",0.5,0)) -> 0 | X29: =if(P29=$Q29,1,if($Q29 = "Tie",0.5,0)) -> 0 | AC29: 1
A30: =vlookup($B30,Matchdays!$A$2:$E$20,3) -> 45073 | B30: 9 | C30: =vlookup($B30,Matchdays!$A$2:$E$20,2) -> 2 | D30: =vlookup($C30,Holidays!$A:$G,2) -> Spain | E30: =vlookup($C30,Holidays!$A:$G,3) -> Murcia | F30: =vlookup($B30,Matchdays!$A$2:$E$20,4) -> Saurines | G30: =vlookup($B30,Matchdays!$A$2:$E$20,5) -> Singles | H30: 23 | I30: Cranham | K30: J. Witt | M30: Europe | O30: USA | Q30: Tie | R30: A/S | S30: =vlookup($C30,Holidays!$A:$G,6) -> D. Witt | T30: =vlookup($C30,Holidays!$A:$G,7) -> McLachlan | U30: =if(M30=$Q30,1,if($Q30 = "Tie",0.5,0)) -> 0.5 | V30: =if(N30=$Q30,1,if($Q30 = "Tie",0.5,0)) -> 0.5 | W30: =if(O30=$Q30,1,if($Q30 = "Tie",0.5,0)) -> 0.5 | X30: =if(P30=$Q30,1,if($Q30 = "Tie",0.5,0)) -> 0.5
A31: =vlookup($B31,Matchdays!$A$2:$E$20,3) -> 45073 | B31: 9 | C31: =vlookup($B31,Matchdays!$A$2:$E$20,2) -> 2 | D31: =vlookup($C31,Holidays!$A:$G,2) -> Spain | E31: =vlookup($C31,Holidays!$A:$G,3) -> Murcia | F31: =vlookup($B31,Matchdays!$A$2:$E$20,4) -> Saurines | G31: =vlookup($B31,Matchdays!$A$2:$E$20,5) -> Singles | H31: 24 | I31: Rogers | K31: Lowy | M31: Europe | O31: USA | Q31: USA | R31: 3&2 | S31: =vlookup($C31,Holidays!$A:$G,6) -> D. Witt | T31: =vlookup($C31,Holidays!$A:$G,7) -> McLachlan | U31: =if(M31=$Q31,1,if($Q31 = "Tie",0.5,0)) -> 0 | V31: =if(N31=$Q31,1,if($Q31 = "Tie",0.5,0)) -> 0 | W31: =if(O31=$Q31,1,if($Q31 = "Tie",0.5,0)) -> 1 | X31: =if(P31=$Q31,1,if($Q31 = "Tie",0.5,0)) -> 0
A32: =vlookup($B32,Matchdays!$A$2:$E$20,3) -> 45073 | B32: 9 | C32: =vlookup($B32,Matchdays!$A$2:$E$20,2) -> 2 | D32: =vlookup($C32,Holidays!$A:$G,2) -> Spain | E32: =vlookup($C32,Holidays!$A:$G,3) -> Murcia | F32: =vlookup($B32,Matchdays!$A$2:$E$20,4) -> Saurines | G32: =vlookup($B32,Matchdays!$A$2:$E$20,5) -> Singles | H32: 25 | I32: Watters | K32: Condon | M32: Europe | O32: USA | Q32: Europe | R32: 2UP | S32: =vlookup($C32,Holidays!$A:$G,6) -> D. Witt | T32: =vlookup($C32,Holidays!$A:$G,7) -> McLachlan | U32: =if(M32=$Q32,1,if($Q32 = "Tie",0.5,0)) -> 1 | V32: =if(N32=$Q32,1,if($Q32 = "Tie",0.5,0)) -> 0 | W32: =if(O32=$Q32,1,if($Q32 = "Tie",0.5,0)) -> 0 | X32: =if(P32=$Q32,1,if($Q32 = "Tie",0.5,0)) -> 0
A33: =vlookup($B33,Matchdays!$A$2:$E$20,3) -> 45547 | B33: 12 | C33: =vlookup($B33,Matchdays!$A$2:$E$20,2) -> 3 | D33: =vlookup($C33,Holidays!$A:$G,2) -> Spain | E33: =vlookup($C33,Holidays!$A:$G,3) -> Malaga | F33: =vlookup($B33,Matchdays!$A$2:$E$20,4) -> Calanova | G33: =vlookup($B33,Matchdays!$A$2:$E$20,5) -> 2x2 Scramble | H33: 26 | I33: Cranham | J33: C. Peters | K33: James | L33: J. Witt | M33: Europe | N33: Europe | O33: USA | P33: USA | Q33: Europe | R33: 3&2 | S33: =vlookup($C33,Holidays!$A:$G,6) -> O'Rourke | T33: =vlookup($C33,Holidays!$A:$G,7) -> Lowy | U33: =if(M33=$Q33,1,if($Q33 = "Tie",0.5,0)) -> 1 | V33: =if(N33=$Q33,1,if($Q33 = "Tie",0.5,0)) -> 1 | W33: =if(O33=$Q33,1,if($Q33 = "Tie",0.5,0)) -> 0 | X33: =if(P33=$Q33,1,if($Q33 = "Tie",0.5,0)) -> 0 | AB33: 1
A34: =vlookup($B34,Matchdays!$A$2:$E$20,3) -> 45547 | B34: 12 | C34: =vlookup($B34,Matchdays!$A$2:$E$20,2) -> 3 | D34: =vlookup($C34,Holidays!$A:$G,2) -> Spain | E34: =vlookup($C34,Holidays!$A:$G,3) -> Malaga | F34: =vlookup($B34,Matchdays!$A$2:$E$20,4) -> Calanova | G34: =vlookup($B34,Matchdays!$A$2:$E$20,5) -> 2x2 Scramble | H34: 27 | I34: J. Barker | J34: Watters | K34: Condon | L34: Lowy | M34: Europe | N34: Europe | O34: USA | P34: USA | Q34: USA | R34: 3&2 | S34: =vlookup($C34,Holidays!$A:$G,6) -> O'Rourke | T34: =vlookup($C34,Holidays!$A:$G,7) -> Lowy | U34: =if(M34=$Q34,1,if($Q34 = "Tie",0.5,0)) -> 0 | V34: =if(N34=$Q34,1,if($Q34 = "Tie",0.5,0)) -> 0 | W34: =if(O34=$Q34,1,if($Q34 = "Tie",0.5,0)) -> 1 | X34: =if(P34=$Q34,1,if($Q34 = "Tie",0.5,0)) -> 1
A35: =vlookup($B35,Matchdays!$A$2:$E$20,3) -> 45547 | B35: 12 | C35: =vlookup($B35,Matchdays!$A$2:$E$20,2) -> 3 | D35: =vlookup($C35,Holidays!$A:$G,2) -> Spain | E35: =vlookup($C35,Holidays!$A:$G,3) -> Malaga | F35: =vlookup($B35,Matchdays!$A$2:$E$20,4) -> Calanova | G35: =vlookup($B35,Matchdays!$A$2:$E$20,5) -> 2x2 Scramble | H35: 28 | I35: O'Rourke | J35: D. Witt | K35: Brown | L35: S. Barker | M35: Europe | N35: Europe | O35: USA | P35: USA | Q35: USA | R35: 3&1 | S35: =vlookup($C35,Holidays!$A:$G,6) -> O'Rourke | T35: =vlookup($C35,Holidays!$A:$G,7) -> Lowy | U35: =if(M35=$Q35,1,if($Q35 = "Tie",0.5,0)) -> 0 | V35: =if(N35=$Q35,1,if($Q35 = "Tie",0.5,0)) -> 0 | W35: =if(O35=$Q35,1,if($Q35 = "Tie",0.5,0)) -> 1 | X35: =if(P35=$Q35,1,if($Q35 = "Tie",0.5,0)) -> 1
A36: =vlookup($B36,Matchdays!$A$2:$E$20,3) -> 45548 | B36: 13 | C36: =vlookup($B36,Matchdays!$A$2:$E$20,2) -> 3 | D36: =vlookup($C36,Holidays!$A:$G,2) -> Spain | E36: =vlookup($C36,Holidays!$A:$G,3) -> Malaga | F36: =vlookup($B36,Matchdays!$A$2:$E$20,4) -> El Chaparral | G36: =vlookup($B36,Matchdays!$A$2:$E$20,5) -> Fourball | H36: 29 | I36: Cranham | J36: D. Witt | K36: Brown | L36: James | M36: Europe | N36: Europe | O36: USA | P36: USA | Q36: Europe | R36: 4&2 | S36: =vlookup($C36,Holidays!$A:$G,6) -> O'Rourke | T36: =vlookup($C36,Holidays!$A:$G,7) -> Lowy | U36: =if(M36=$Q36,1,if($Q36 = "Tie",0.5,0)) -> 1 | V36: =if(N36=$Q36,1,if($Q36 = "Tie",0.5,0)) -> 1 | W36: =if(O36=$Q36,1,if($Q36 = "Tie",0.5,0)) -> 0 | X36: =if(P36=$Q36,1,if($Q36 = "Tie",0.5,0)) -> 0 | AC36: 3
A37: =vlookup($B37,Matchdays!$A$2:$E$20,3) -> 45548 | B37: 13 | C37: =vlookup($B37,Matchdays!$A$2:$E$20,2) -> 3 | D37: =vlookup($C37,Holidays!$A:$G,2) -> Spain | E37: =vlookup($C37,Holidays!$A:$G,3) -> Malaga | F37: =vlookup($B37,Matchdays!$A$2:$E$20,4) -> El Chaparral | G37: =vlookup($B37,Matchdays!$A$2:$E$20,5) -> Fourball | H37: 30 | I37: O'Rourke | J37: J. Barker | K37: Lowy | L37: J. Witt | M37: Europe | N37: Europe | O37: USA | P37: USA | Q37: USA | R37: 7&5 | S37: =vlookup($C37,Holidays!$A:$G,6) -> O'Rourke | T37: =vlookup($C37,Holidays!$A:$G,7) -> Lowy | U37: =if(M37=$Q37,1,if($Q37 = "Tie",0.5,0)) -> 0 | V37: =if(N37=$Q37,1,if($Q37 = "Tie",0.5,0)) -> 0 | W37: =if(O37=$Q37,1,if($Q37 = "Tie",0.5,0)) -> 1 | X37: =if(P37=$Q37,1,if($Q37 = "Tie",0.5,0)) -> 1 | AC37: 1 | AE37: 1
A38: =vlookup($B38,Matchdays!$A$2:$E$20,3) -> 45548 | B38: 13 | C38: =vlookup($B38,Matchdays!$A$2:$E$20,2) -> 3 | D38: =vlookup($C38,Holidays!$A:$G,2) -> Spain | E38: =vlookup($C38,Holidays!$A:$G,3) -> Malaga | F38: =vlookup($B38,Matchdays!$A$2:$E$20,4) -> El Chaparral | G38: =vlookup($B38,Matchdays!$A$2:$E$20,5) -> Fourball | H38: 31 | I38: C. Peters | J38: Watters | K38: Condon | L38: S. Barker | M38: Europe | N38: Europe | O38: USA | P38: USA | Q38: Europe | R38: 3&2 | S38: =vlookup($C38,Holidays!$A:$G,6) -> O'Rourke | T38: =vlookup($C38,Holidays!$A:$G,7) -> Lowy | U38: =if(M38=$Q38,1,if($Q38 = "Tie",0.5,0)) -> 1 | V38: =if(N38=$Q38,1,if($Q38 = "Tie",0.5,0)) -> 1 | W38: =if(O38=$Q38,1,if($Q38 = "Tie",0.5,0)) -> 0 | X38: =if(P38=$Q38,1,if($Q38 = "Tie",0.5,0)) -> 0
A39: =vlookup($B39,Matchdays!$A$2:$E$20,3) -> 45550 | B39: 14 | C39: =vlookup($B39,Matchdays!$A$2:$E$20,2) -> 3 | D39: =vlookup($C39,Holidays!$A:$G,2) -> Spain | E39: =vlookup($C39,Holidays!$A:$G,3) -> Malaga | F39: =vlookup($B39,Matchdays!$A$2:$E$20,4) -> La Cala (Asia) | G39: =vlookup($B39,Matchdays!$A$2:$E$20,5) -> Singles | H39: 32 | I39: O'Rourke | K39: Lowy | M39: Europe | O39: USA | Q39: USA | R39: 1UP | S39: =vlookup($C39,Holidays!$A:$G,6) -> O'Rourke | T39: =vlookup($C39,Holidays!$A:$G,7) -> Lowy | U39: =if(M39=$Q39,1,if($Q39 = "Tie",0.5,0)) -> 0 | V39: =if(N39=$Q39,1,if($Q39 = "Tie",0.5,0)) -> 0 | W39: =if(O39=$Q39,1,if($Q39 = "Tie",0.5,0)) -> 1 | X39: =if(P39=$Q39,1,if($Q39 = "Tie",0.5,0)) -> 0
A40: =vlookup($B40,Matchdays!$A$2:$E$20,3) -> 45550 | B40: 14 | C40: =vlookup($B40,Matchdays!$A$2:$E$20,2) -> 3 | D40: =vlookup($C40,Holidays!$A:$G,2) -> Spain | E40: =vlookup($C40,Holidays!$A:$G,3) -> Malaga | F40: =vlookup($B40,Matchdays!$A$2:$E$20,4) -> La Cala (Asia) | G40: =vlookup($B40,Matchdays!$A$2:$E$20,5) -> Singles | H40: 33 | I40: Watters | K40: James | M40: Europe | O40: USA | Q40: Tie | R40: A/S | S40: =vlookup($C40,Holidays!$A:$G,6) -> O'Rourke | T40: =vlookup($C40,Holidays!$A:$G,7) -> Lowy | U40: =if(M40=$Q40,1,if($Q40 = "Tie",0.5,0)) -> 0.5 | V40: =if(N40=$Q40,1,if($Q40 = "Tie",0.5,0)) -> 0.5 | W40: =if(O40=$Q40,1,if($Q40 = "Tie",0.5,0)) -> 0.5 | X40: =if(P40=$Q40,1,if($Q40 = "Tie",0.5,0)) -> 0.5 | AC40: 1
...

Sheet Players
A1: player_id | B1: name | C1: first_name | D1: last_name | E1: attending | F1: handicap_1 | G1: handicap_2 | H1: handicap_3 | I1: handicap_4
A2: 1 | B2: J. Witt | C2: James | D2: Witt | E2: 1
A3: 2 | B3: Watters | C3: Cameron | D3: Watters | E3: 1
A4: 3 | B4: D. Witt | C4: Daniel | D4: Witt | E4: 1
A5: 4 | B5: Lowy | C5: Gregory | D5: Lowy | E5: 1
A6: 5 | B6: James | C6: Alexander | D6: James | E6: 1
A7: 6 | B7: S. Barker | C7: Simon | D7: Barker | E7: 1
A8: 7 | B8: O'Rourke | C8: Michael | D8: O'Rourke | E8: 1
A9: 8 | B9: Cranham | C9: Alexander | D9: Cranham | E9: 0
A10: 9 | B10: C. Peters | C10: Callum | D10: Peters | E10: 1
A11: 10 | B11: McLachlan | C11: Joel | D11: McLachlan | E11: 0
A12: 11 | B12: Condon | C12: Jack | D12: Condon | E12: 1
A13: 12 | B13: Mulligan | C13: Thomas | D13: Mulligan | E13: 0
... A19: 18 | B19: Champion | C19: Ollie | D19: Champion | E19: 1

Sheet Green Jackets
A1: event_id | B1: holiday_id | C1: date | D1: country | E1: area | F1: course | G1: player | H1: rank | I1: score | J1: chip_ins | K1: birdies
A2: 18 | B2: 4 | C2: =vlookup($A2,Matchdays!$A:$G,3,false) -> 45794 | D2: =vlookup($B2,Holidays!$A:$I,2) -> Turkey | E2: =vlookup($B2,Holidays!$A:$I,3) -> Belek | F2: =vlookup($A2,Matchdays!$A:$G,4,false) -> Montgomerie | G2: Watters | H2: 1 | I2: 39 | J2: 0
A3: 18 | B3: 4 | C3: =vlookup($A3,Matchdays!$A:$G,3,false) -> 45794 | D3: =vlookup($B3,Holidays!$A:$I,2) -> Turkey | E3: =vlookup($B3,Holidays!$A:$I,3) -> Belek | F3: =vlookup($A3,Matchdays!$A:$G,4,false) -> Montgomerie | G3: C. Peters | H3: 2 | I3: 34 | J3: 0 | K3: 1
A4: 18 | B4: 4 | C4: =vlookup($A4,Matchdays!$A:$G,3,false) -> 45794 | D4: =vlookup($B4,Holidays!$A:$I,2) -> Turkey | E4: =vlookup($B4,Holidays!$A:$I,3) -> Belek | F4: =vlookup($A4,Matchdays!$A:$G,4,false) -> Montgomerie | G4: J. Witt | H4: 3 | I4: 34 | J4: 0
A5: 18 | B5: 4 | C5: =vlookup($A5,Matchdays!$A:$G,3,false) -> 45794 | D5: =vlookup($B5,Holidays!$A:$I,2) -> Turkey | E5: =vlookup($B5,Holidays!$A:$I,3) -> Belek | F5: =vlookup($A5,Matchdays!$A:$G,4,false) -> Montgomerie | G5: James | H5: 4 | I5: 34 | J5: 0
A6: 18 | B6: 4 | C6: =vlookup($A6,Matchdays!$A:$G,3,false) -> 45794 | D6: =vlookup($B6,Holidays!$A:$I,2) -> Turkey | E6: =vlookup($B6,Holidays!$A:$I,3) -> Belek | F6: =vlookup($A6,Matchdays!$A:$G,4,false) -> Montgomerie | G6: Condon | H6: 5 | I6: 32 | J6: 0 | K6: 2
A7: 18 | B7: 4 | C7: =vlookup($A7,Matchdays!$A:$G,3,false) -> 45794 | D7: =vlookup($B7,Holidays!$A:$I,2) -> Turkey | E7: =vlookup($B7,Holidays!$A:$I,3) -> Belek | F7: =vlookup($A7,Matchdays!$A:$G,4,false) -> Montgomerie | G7: Lowy | H7: 6 | I7: 31 | J7: 0
A8: 18 | B8: 4 | C8: =vlookup($A8,Matchdays!$A:$G,3,false) -> 45794 | D8: =vlookup($B8,Holidays!$A:$I,2) -> Turkey | E8: =vlookup($B8,Holidays!$A:$I,3) -> Belek | F8: =vlookup($A8,Matchdays!$A:$G,4,false) -> Montgomerie | G8: S. Barker | H8: 7 | I8: 29 | J8: 0
A9: 18 | B9: 4 | C9: =vlookup($A9,Matchdays!$A:$G,3,false) -> 45794 | D9: =vlookup($B9,Holidays!$A:$I,2) -> Turkey | E9: =vlookup($B9,Holidays!$A:$I,3) -> Belek | F9: =vlookup($A9,Matchdays!$A:$G,4,false) -> Montgomerie | G9: Cranham | H9: 8 | I9: 28 | J9: 0 | K9: 1
A10: 18 | B10: 4 | C10: =vlookup($A10,Matchdays!$A:$G,3,false) -> 45794 | D10: =vlookup($B10,Holidays!$A:$I,2) -> Turkey | E10: =vlookup($B10,Holidays!$A:$I,3) -> Belek | F10: =vlookup($A10,Matchdays!$A:$G,4,false) -> Montgomerie | G10: O'Rourke | H10: 9 | I10: 28 | J10: 0 | K10: 3
A11: 18 | B11: 4 | C11: =vlookup($A11,Matchdays!$A:$G,3,false) -> 45794 | D11: =vlookup($B11,Holidays!$A:$I,2) -> Turkey | E11: =vlookup($B11,Holidays!$A:$I,3) -> Belek | F11: =vlookup($A11,Matchdays!$A:$G,4,false) -> Montgomerie | G11: McLachlan | H11: 10 | I11: 23 | J11: 0
A12: 18 | B12: 4 | C12: =vlookup($A12,Matchdays!$A:$G,3,false) -> 45794 | D12: =vlookup($B12,Holidays!$A:$I,2) -> Turkey | E12: =vlookup($B12,Holidays!$A:$I,3) -> Belek | F12: =vlookup($A12,Matchdays!$A:$G,4,false) -> Montgomerie | G12: Mulligan | H12: 11 | I12: 23 | J12: 0
A13: 18 | B13: 4 | C13: =vlookup($A13,Matchdays!$A:$G,3,false) -> 45794 | D13: =vlookup($B13,Holidays!$A:$I,2) -> Turkey | E13: =vlookup($B13,Holidays!$A:$I,3) -> Belek | F13: =vlookup($A13,Matchdays!$A:$G,4,false) -> Montgomerie | G13: D. Witt | H13: Cup-tied
A14: 11 | B14: 3 | C14: =vlookup($A14,Matchdays!$A:$G,3,false) -> 45546 | D14: =vlookup($B14,Holidays!$A:$I,2) -> Spain | E14: =vlookup($B14,Holidays!$A:$I,3) -> Malaga | F14: =vlookup($A14,Matchdays!$A:$G,4,false) -> Miguel Angel Jimenez Academy | G14: Lowy | H14: 1
A15: 11 | B15: 3 | C15: =vlookup($A15,Matchdays!$A:$G,3,false) -> 45546 | D15: =vlookup($B15,Holidays!$A:$I,2) -> Spain | E15: =vlookup($B15,Holidays!$A:$I,3) -> Malaga | F15: =vlookup($A15,Matchdays!$A:$G,4,false) -> Miguel Angel Jimenez Academy | G15: James | H15: 2
A16: 11 | B16: 3 | C16: =vlookup($A16,Matchdays!$A:$G,3,false) -> 45546 | D16: =vlookup($B16,Holidays!$A:$I,2) -> Spain | E16: =vlookup($B16,Holidays!$A:$I,3) -> Malaga | F16: =vlookup($A16,Matchdays!$A:$G,4,false) -> Miguel Angel Jimenez Academy | G16: C. Peters | H16: 3
A17: 11 | B17: 3 | C17: =vlookup($A17,Matchdays!$A:$G,3,false) -> 45546 | D17: =vlookup($B17,Holidays!$A:$I,2) -> Spain | E17: =vlookup($B17,Holidays!$A:$I,3) -> Malaga | F17: =vlookup($A17,Matchdays!$A:$G,4,false) -> Miguel Angel Jimenez Academy | G17: Condon | H17: 4
A18: 11 | B18: 3 | C18: =vlookup($A18,Matchdays!$A:$G,3,false) -> 45546 | D18: =vlookup($B18,Holidays!$A:$I,2) -> Spain | E18: =vlookup($B18,Holidays!$A:$I,3) -> Malaga | F18: =vlookup($A18,Matchdays!$A:$G,4,false) -> Miguel Angel Jimenez Academy | G18: Brown | H18: 5
A19: 11 | B19: 3 | C19: =vlookup($A19,Matchdays!$A:$G,3,false) -> 45546 | D19: =vlookup($B19,Holidays!$A:$I,2) -> Spain | E19: =vlookup($B19,Holidays!$A:$I,3) -> Malaga | F19: =vlookup($A19,Matchdays!$A:$G,4,false) -> Miguel Angel Jimenez Academy | G19: S. Barker | H19: 6
A20: 11 | B20: 3 | C20: =vlookup($A20,Matchdays!$A:$G,3,false) -> 45546 | D20: =vlookup($B20,Holidays!$A:$I,2) -> Spain | E20: =vlookup($B20,Holidays!$A:$I,3) -> Malaga | F20: =vlookup($A20,Matchdays!$A:$G,4,false) -> Miguel Angel Jimenez Academy | G20: J. Barker | H20: 7
A21: 11 | B21: 3 | C21: =vlookup($A21,Matchdays!$A:$G,3,false) -> 45546 | D21: =vlookup($B21,Holidays!$A:$I,2) -> Spain | E21: =vlookup($B21,Holidays!$A:$I,3) -> Malaga | F21: =vlookup($A21,Matchdays!$A:$G,4,false) -> Miguel Angel Jimenez Academy | G21: Cranham | H21: 8
A22: 11 | B22: 3 | C22: =vlookup($A22,Matchdays!$A:$G,3,false) -> 45546 | D22: =vlookup($B22,Holidays!$A:$I,2) -> Spain | E22: =vlookup($B22,Holidays!$A:$I,3) -> Malaga | F22: =vlookup($A22,Matchdays!$A:$G,4,false) -> Miguel Angel Jimenez Academy | G22: J. Witt | H22: 9
A23: 11 | B23: 3 | C23: =vlookup($A23,Matchdays!$A:$G,3,false) -> 45546 | D23: =vlookup($B23,Holidays!$A:$I,2) -> Spain | E23: =vlookup($B23,Holidays!$A:$I,3) -> Malaga | F23: =vlookup($A23,Matchdays!$A:$G,4,false) -> Miguel Angel Jimenez Academy | G23: O'Rourke | H23: 10
A24: 11 | B24: 3 | C24: =vlookup($A24,Matchdays!$A:$G,3,false) -> 45546 | D24: =vlookup($B24,Holidays!$A:$I,2) -> Spain | E24: =vlookup($B24,Holidays!$A:$I,3) -> Malaga | F24: =vlookup($A24,Matchdays!$A:$G,4,false) -> Miguel Angel Jimenez Academy | G24: D. Witt | H24: 11
A25: 11 | B25: 3 | C25: =vlookup($A25,Matchdays!$A:$G,3,false) -> 45546 | D25: =vlookup($B25,Holidays!$A:$I,2) -> Spain | E25: =vlookup($B25,Holidays!$A:$I,3) -> Malaga | F25: =vlookup($A25,Matchdays!$A:$G,4,false) -> Miguel Angel Jimenez Academy | G25: Watters | H25: 12
A26: 10 | B26: 2 | C26: =vlookup($A26,Matchdays!$A:$G,3,false) -> 45074 | D26: =vlookup($B26,Holidays!$A:$I,2) -> Spain | E26: =vlookup($B26,Holidays!$A:$I,3) -> Murcia | F26: =vlookup($A26,Matchdays!$A:$G,4,false) -> Saurines | G26: D. Witt | H26: 1
A27: 10 | B27: 2 | C27: =vlookup($A27,Matchdays!$A:$G,3,false) -> 45074 | D27: =vlookup($B27,Holidays!$A:$I,2) -> Spain | E27: =vlookup($B27,Holidays!$A:$I,3) -> Murcia | F27: =vlookup($A27,Matchdays!$A:$G,4,false) -> Saurines | G27: Watters | H27: Unknown
A28: 10 | B28: 2 | C28: =vlookup($A28,Matchdays!$A:$G,3,false) -> 45074 | D28: =vlookup($B28,Holidays!$A:$I,2) -> Spain | E28: =vlookup($B28,Holidays!$A:$I,3) -> Murcia | F28: =vlookup($A28,Matchdays!$A:$G,4,false) -> Saurines | G28: O'Rourke | H28: Unknown | K28: 1
A29: 10 | B29: 2 | C29: =vlookup($A29,Matchdays!$A:$G,3,false) -> 45074 | D29: =vlookup($B29,Holidays!$A:$I,2) -> Spain | E29: =vlookup($B29,Holidays!$A:$I,3) -> Murcia | F29: =vlookup($A29,Matchdays!$A:$G,4,false) -> Saurines | G29: Lowy | H29: Unknown
A30: 10 | B30: 2 | C30: =vlookup($A30,Matchdays!$A:$G,3,false) -> 45074 | D30: =vlookup($B30,Holidays!$A:$I,2) -> Spain | E30: =vlookup($B30,Holidays!$A:$I,3) -> Murcia | F30: =vlookup($A30,Matchdays!$A:$G,4,false) -> Saurines | G30: J. Witt | H30: Unknown
A31: 10 | B31: 2 | C31: =vlookup($A31,Matchdays!$A:$G,3,false) -> 45074 | D31: =vlookup($B31,Holidays!$A:$I,2) -> Spain | E31: =vlookup($B31,Holidays!$A:$I,3) -> Murcia | F31: =vlookup($A31,Matchdays!$A:$G,4,false) -> Saurines | G31: C. Peters | H31: Unknown
A32: 10 | B32: 2 | C32: =vlookup($A32,Matchdays!$A:$G,3,false) -> 45074 | D32: =vlookup($B32,Holidays!$A:$I,2) -> Spain | E32: =vlookup($B32,Holidays!$A:$I,3) -> Murcia | F32: =vlookup($A32,Matchdays!$A:$G,4,false) -> Saurines | G32: McLachlan | H32: Unknown
A33: 10 | B33: 2 | C33: =vlookup($A33,Matchdays!$A:$G,3,false) -> 45074 | D33: =vlookup($B33,Holidays!$A:$I,2) -> Spain | E33: =vlookup($B33,Holidays!$A:$I,3) -> Murcia | F33: =vlookup($A33,Matchdays!$A:$G,4,false) -> Saurines | G33: Cranham | H33: Unknown
A34: 10 | B34: 2 | C34: =vlookup($A34,Matchdays!$A:$G,3,false) -> 45074 | D34: =vlookup($B34,Holidays!$A:$I,2) -> Spain | E34: =vlookup($B34,Holidays!$A:$I,3) -> Murcia | F34: =vlookup($A34,Matchdays!$A:$G,4,false) -> Saurines | G34: James | H34: Unknown
A35: 10 | B35: 2 | C35: =vlookup($A35,Matchdays!$A:$G,3,false) -> 45074 | D35: =vlookup($B35,Holidays!$A:$I,2) -> Spain | E35: =vlookup($B35,Holidays!$A:$I,3) -> Murcia | F35: =vlookup($A35,Matchdays!$A:$G,4,false) -> Saurines | G35: Rogers | H35: DNS
A36: 10 | B36: 2 | C36: =vlookup($A36,Matchdays!$A:$G,3,false) -> 45074 | D36: =vlookup($B36,Holidays!$A:$I,2) -> Spain | E36: =vlookup($B36,Holidays!$A:$I,3) -> Murcia | F36: =vlookup($A36,Matchdays!$A:$G,4,false) -> Saurines | G36: Condon | H36: DNS
A37: 10 | B37: 2 | C37: =vlookup($A37,Matchdays!$A:$G,3,false) -> 45074 | D37: =vlookup($B37,Holidays!$A:$I,2) -> Spain | E37: =vlookup($B37,Holidays!$A:$I,3) -> Murcia | F37: =vlookup($A37,Matchdays!$A:$G,4,false) -> Saurines | G37: S. Barker | H37: DNS

Sheet Sheet10
B1: Player | C1: Apps | D1: Total Pts | E1: Total Pts | F1: PPG | G1: T Scramble Record | H1: Pairs Record | I1: Singles Record | J1: Kingpin | K1: Birdies | L1: Eagles | M1: Chip-Ins | N1: Long Drive | O1: Near Pin | P1: Singles | Q1: DOTD
A2: 1 | B2: Lowy | C2: 4 | D2: 8 | E2: 10 | F2: 0.62 | G2: 0/0/0/2 | H2: 4/2 (0 ties) | I2: 4/1 (0 ties) | J2: 0/0 | K2: 1 | L2: 0 | M2: 0 | N2: 0 | O2: 0 | P2: 1 | Q2: 0
A3: 2 | B3: Watters | C3: 4 | D3: 7.63 | E3: 10 | F3: 0.59 | G3: 0/1/1/0 | H3: 3/3 (1 ties) | I3: 3/0 (1 ties) | J3: 0/0 | K3: 2 | L3: 0 | M3: 0 | N3: 0 | O3: 0 | P3: 1 | Q3: 1
A4: 3 | B4: James | C4: 4 | D4: 7.33 | E4: 10 | F4: 0.56 | G4: 1/0/0/1 | H4: 4/3 (0 ties) | I4: 2/1 (1 ties) | J4: 0/0 | K4: 0 | L4: 0 | M4: 1 | N4: 0 | O4: 1 | P4: 0 | Q4: 4
A5: 3 | B5: O'Rourke | C5: 4 | D5: 7.33 | E5: 9.5 | F5: 0.56 | G5: 1/1/0/0 | H5: 3/2 (1 ties) | I5: 2/2 (1 ties) | J5: 0/0 | K5: 11 | L5: 0 | M5: 0 | N5: 2 | O5: 1 | P5: 0 | Q5: 0
A6: 5 | B6: J.Witt | C6: 4 | D6: 7 | E6: 9.5 | F6: 0.54 | G6: 1/0/0/1 | H6: 3/2 (1 ties) | I6: 2/1 (1 ties) | J6: 1/0 | K6: 2 | L6: 0 | M6: 1 | N6: 0 | O6: 1 | P6: 0 | Q6: 0
A7: 6 | B7: C. Peters | C7: 4 | D7: 6.63 | E7: 9 | F7: 0.51 | G7: 0/1/1/0 | H7: 5/1 (0 ties) | I7: 1/3 (0 ties) | J7: 0/1 | K7: 4 | L7: 0 | M7: 1 | N7: 0 | O7: 0 | P7: 0 | Q7: 1
A8: 7 | B8: Condon | C8: 4 | D8: 6.33 | E8: 9 | F8: 0.45 | G8: 2/0/0/0 | H8: 3/5 (0 ties) | I8: 1/2 (1 ties) | J8: 0/0 | K8: 3 | L8: 0 | M8: 1 | N8: 1 | O8: 0 | P8: 0 | Q8: 5
A9: 8 | B9: Cranham | C9: 4 | D9: 6.13 | E9: 8 | F9: 0.47 | G9: 0/1/1/0 | H9: 4/3 (0 ties) | I9: 1/2 (1 ties) | J9: 0/0 | K9: 10 | L9: 0 | M9: 0 | N9: 1 | O9: 1 | P9: 0 | Q9: 0
A10: 9 | B10: McLachlan | C10: 3 | D10: 5.33 | E10: 8 | F10: 0.48 | G10: 2/0/0/0 | H10: 1/3 (1 ties) | I10: 2/2 (0 ties) | J10: 0/0 | K10: 2 | L10: 0 | M10: 0 | N10: 0 | O10: 0 | P10: 0 | Q10: 1
A11: 10 | B11: D.Witt | C11: 4 | D11: 4.83 | E11: 7.5 | F11: 0.37 | G11: 1/1/0/0 | H11: 2/5 (0 ties) | I11: 1/2 (1 ties) | J11: 0/0 | K11: 0 | L11: 0 | M11: 2 | N11: 0 | O11: 0 | P11: 1 | Q11: 1
A12: 11 | B12: S. Barker | C12: 4 | D12: 4.5 | E12: 6 | F12: 0.35 | G12: 0/0/0/2 | H12: 2/5 (0 ties) | I12: 2/1 (1 ties) | J12: 0/0 | K12: 0 | L12: 0 | M12: 0 | N12: 0 | O12: 0 | P12: 0 | Q12: 2
A13: 12 | B13: Mulligan | C13: 2 | D13: 3.33 | E13: 4.5 | F13: 0.48 | G13: 1/1/0/0 | H13: 2/1 (0 ties) | I13: 0/2 (0 ties) | J13: 0/0 | K13: 0 | L13: 0 | M13: 1 | N13: 0 | O13: 0 | P13: 0 | Q13: 1
... A16: 15 | B16: J. Barker | C16: 1 | D16: 0 | E16: 0 | F16: 0 | G16: 0/0/0/0 | H16: 0/2 (0 ties) | I16: 0/1 (0 ties) | J16: 0/0 | K16: 1 | L16: 0 | M16: 1 | N16: 0 | O16: 0 | P16: 0 | Q16: 0
